[2024-05-18T18:57:45.046+0000] {task_context_logger.py:104} ERROR - Executor reports task instance <TaskInstance: data_loader.hello_task scheduled__2022-08-16T01:00:00+00:00 [queued]> finished (failed) although the task says it's queued. (Info: None) Was the task killed externally?
