[2024-05-18T19:41:31.473+0000] {local_task_job_runner.py:120} INFO - ::group::Pre task execution logs
[2024-05-18T19:41:31.491+0000] {taskinstance.py:2076} INFO - Dependencies all met for dep_context=non-requeueable deps ti=<TaskInstance: data_loader.upload_file manual__2024-05-18T19:41:26.448400+00:00 [queued]>
[2024-05-18T19:41:31.500+0000] {taskinstance.py:2076} INFO - Dependencies all met for dep_context=requeueable deps ti=<TaskInstance: data_loader.upload_file manual__2024-05-18T19:41:26.448400+00:00 [queued]>
[2024-05-18T19:41:31.501+0000] {taskinstance.py:2306} INFO - Starting attempt 1 of 2
[2024-05-18T19:41:31.515+0000] {taskinstance.py:2330} INFO - Executing <Task(LocalFilesystemToGCSOperator): upload_file> on 2024-05-18 19:41:26.448400+00:00
[2024-05-18T19:41:31.522+0000] {warnings.py:110} WARNING - /home/***/.local/lib/python3.12/site-packages/***/task/task_runner/standard_task_runner.py:61: DeprecationWarning: This process (pid=1697) is multi-threaded, use of fork() may lead to deadlocks in the child.
  pid = os.fork()

[2024-05-18T19:41:31.524+0000] {standard_task_runner.py:63} INFO - Started process 1699 to run task
[2024-05-18T19:41:31.523+0000] {standard_task_runner.py:90} INFO - Running: ['***', 'tasks', 'run', 'data_loader', 'upload_file', 'manual__2024-05-18T19:41:26.448400+00:00', '--job-id', '336', '--raw', '--subdir', 'DAGS_FOLDER/data_loader.py', '--cfg-path', '/tmp/tmpg3hdq036']
[2024-05-18T19:41:31.526+0000] {standard_task_runner.py:91} INFO - Job 336: Subtask upload_file
[2024-05-18T19:41:31.565+0000] {task_command.py:426} INFO - Running <TaskInstance: data_loader.upload_file manual__2024-05-18T19:41:26.448400+00:00 [running]> on host b5cbc22da81e
[2024-05-18T19:41:31.627+0000] {taskinstance.py:2648} INFO - Exporting env vars: AIRFLOW_CTX_DAG_OWNER='***' AIRFLOW_CTX_DAG_ID='data_loader' AIRFLOW_CTX_TASK_ID='upload_file' AIRFLOW_CTX_EXECUTION_DATE='2024-05-18T19:41:26.448400+00:00' AIRFLOW_CTX_TRY_NUMBER='1' AIRFLOW_CTX_DAG_RUN_ID='manual__2024-05-18T19:41:26.448400+00:00'
[2024-05-18T19:41:31.629+0000] {taskinstance.py:430} INFO - ::endgroup::
[2024-05-18T19:41:31.636+0000] {taskinstance.py:441} INFO - ::group::Post task execution logs
[2024-05-18T19:41:31.643+0000] {taskinstance.py:2905} ERROR - Task failed with exception
Traceback (most recent call last):
  File "/home/airflow/.local/lib/python3.12/site-packages/airflow/models/taskinstance.py", line 465, in _execute_task
    result = _execute_callable(context=context, **execute_callable_kwargs)
             ^^^^^^^^^^^^^^^^^^^^^^^^^^^^^^^^^^^^^^^^^^^^^^^^^^^^^^^^^^^^^
  File "/home/airflow/.local/lib/python3.12/site-packages/airflow/models/taskinstance.py", line 432, in _execute_callable
    return execute_callable(context=context, **execute_callable_kwargs)
           ^^^^^^^^^^^^^^^^^^^^^^^^^^^^^^^^^^^^^^^^^^^^^^^^^^^^^^^^^^^^
  File "/home/airflow/.local/lib/python3.12/site-packages/airflow/models/baseoperator.py", line 400, in wrapper
    return func(self, *args, **kwargs)
           ^^^^^^^^^^^^^^^^^^^^^^^^^^^
  File "/home/airflow/.local/lib/python3.12/site-packages/airflow/providers/google/cloud/transfers/local_to_gcs.py", line 91, in execute
    hook = GCSHook(
           ^^^^^^^^
  File "/home/airflow/.local/lib/python3.12/site-packages/airflow/providers/google/cloud/hooks/gcs.py", line 160, in __init__
    super().__init__(
  File "/home/airflow/.local/lib/python3.12/site-packages/airflow/providers/google/common/hooks/base_google.py", line 252, in __init__
    self.extras: dict = self.get_connection(self.gcp_conn_id).extra_dejson
                        ^^^^^^^^^^^^^^^^^^^^^^^^^^^^^^^^^^^^^
  File "/home/airflow/.local/lib/python3.12/site-packages/airflow/hooks/base.py", line 83, in get_connection
    conn = Connection.get_connection_from_secrets(conn_id)
           ^^^^^^^^^^^^^^^^^^^^^^^^^^^^^^^^^^^^^^^^^^^^^^^
  File "/home/airflow/.local/lib/python3.12/site-packages/airflow/models/connection.py", line 519, in get_connection_from_secrets
    raise AirflowNotFoundException(f"The conn_id `{conn_id}` isn't defined")
airflow.exceptions.AirflowNotFoundException: The conn_id `google_cloud_default` isn't defined
[2024-05-18T19:41:31.647+0000] {taskinstance.py:1206} INFO - Marking task as UP_FOR_RETRY. dag_id=data_loader, task_id=upload_file, run_id=manual__2024-05-18T19:41:26.448400+00:00, execution_date=20240518T194126, start_date=20240518T194131, end_date=20240518T194131
[2024-05-18T19:41:31.657+0000] {standard_task_runner.py:110} ERROR - Failed to execute job 336 for task upload_file (The conn_id `google_cloud_default` isn't defined; 1699)
[2024-05-18T19:41:31.699+0000] {local_task_job_runner.py:240} INFO - Task exited with return code 1
[2024-05-18T19:41:31.720+0000] {taskinstance.py:3498} INFO - 0 downstream tasks scheduled from follow-on schedule check
[2024-05-18T19:41:31.723+0000] {local_task_job_runner.py:222} INFO - ::endgroup::
