[2024-05-18T19:32:26.359+0000] {local_task_job_runner.py:120} INFO - ::group::Pre task execution logs
[2024-05-18T19:32:26.372+0000] {taskinstance.py:2076} INFO - Dependencies all met for dep_context=non-requeueable deps ti=<TaskInstance: data_loader.upload_file scheduled__2023-06-19T01:00:00+00:00 [queued]>
[2024-05-18T19:32:26.379+0000] {taskinstance.py:2076} INFO - Dependencies all met for dep_context=requeueable deps ti=<TaskInstance: data_loader.upload_file scheduled__2023-06-19T01:00:00+00:00 [queued]>
[2024-05-18T19:32:26.380+0000] {taskinstance.py:2306} INFO - Starting attempt 1 of 2
[2024-05-18T19:32:26.392+0000] {taskinstance.py:2330} INFO - Executing <Task(LocalFilesystemToGCSOperator): upload_file> on 2023-06-19 01:00:00+00:00
[2024-05-18T19:32:26.398+0000] {warnings.py:110} WARNING - /home/***/.local/lib/python3.12/site-packages/***/task/task_runner/standard_task_runner.py:61: DeprecationWarning: This process (pid=1559) is multi-threaded, use of fork() may lead to deadlocks in the child.
  pid = os.fork()

[2024-05-18T19:32:26.400+0000] {standard_task_runner.py:63} INFO - Started process 1561 to run task
[2024-05-18T19:32:26.399+0000] {standard_task_runner.py:90} INFO - Running: ['***', 'tasks', 'run', 'data_loader', 'upload_file', 'scheduled__2023-06-19T01:00:00+00:00', '--job-id', '329', '--raw', '--subdir', 'DAGS_FOLDER/data_loader.py', '--cfg-path', '/tmp/tmp3wflq4kv']
[2024-05-18T19:32:26.401+0000] {standard_task_runner.py:91} INFO - Job 329: Subtask upload_file
[2024-05-18T19:32:26.440+0000] {task_command.py:426} INFO - Running <TaskInstance: data_loader.upload_file scheduled__2023-06-19T01:00:00+00:00 [running]> on host b5cbc22da81e
[2024-05-18T19:32:26.507+0000] {taskinstance.py:2648} INFO - Exporting env vars: AIRFLOW_CTX_DAG_OWNER='***' AIRFLOW_CTX_DAG_ID='data_loader' AIRFLOW_CTX_TASK_ID='upload_file' AIRFLOW_CTX_EXECUTION_DATE='2023-06-19T01:00:00+00:00' AIRFLOW_CTX_TRY_NUMBER='1' AIRFLOW_CTX_DAG_RUN_ID='scheduled__2023-06-19T01:00:00+00:00'
[2024-05-18T19:32:26.509+0000] {taskinstance.py:430} INFO - ::endgroup::
[2024-05-18T19:32:26.516+0000] {taskinstance.py:441} INFO - ::group::Post task execution logs
[2024-05-18T19:32:26.524+0000] {taskinstance.py:2905} ERROR - Task failed with exception
Traceback (most recent call last):
  File "/home/airflow/.local/lib/python3.12/site-packages/airflow/models/taskinstance.py", line 465, in _execute_task
    result = _execute_callable(context=context, **execute_callable_kwargs)
             ^^^^^^^^^^^^^^^^^^^^^^^^^^^^^^^^^^^^^^^^^^^^^^^^^^^^^^^^^^^^^
  File "/home/airflow/.local/lib/python3.12/site-packages/airflow/models/taskinstance.py", line 432, in _execute_callable
    return execute_callable(context=context, **execute_callable_kwargs)
           ^^^^^^^^^^^^^^^^^^^^^^^^^^^^^^^^^^^^^^^^^^^^^^^^^^^^^^^^^^^^
  File "/home/airflow/.local/lib/python3.12/site-packages/airflow/models/baseoperator.py", line 400, in wrapper
    return func(self, *args, **kwargs)
           ^^^^^^^^^^^^^^^^^^^^^^^^^^^
  File "/home/airflow/.local/lib/python3.12/site-packages/airflow/providers/google/cloud/transfers/local_to_gcs.py", line 91, in execute
    hook = GCSHook(
           ^^^^^^^^
  File "/home/airflow/.local/lib/python3.12/site-packages/airflow/providers/google/cloud/hooks/gcs.py", line 160, in __init__
    super().__init__(
  File "/home/airflow/.local/lib/python3.12/site-packages/airflow/providers/google/common/hooks/base_google.py", line 252, in __init__
    self.extras: dict = self.get_connection(self.gcp_conn_id).extra_dejson
                        ^^^^^^^^^^^^^^^^^^^^^^^^^^^^^^^^^^^^^
  File "/home/airflow/.local/lib/python3.12/site-packages/airflow/hooks/base.py", line 83, in get_connection
    conn = Connection.get_connection_from_secrets(conn_id)
           ^^^^^^^^^^^^^^^^^^^^^^^^^^^^^^^^^^^^^^^^^^^^^^^
  File "/home/airflow/.local/lib/python3.12/site-packages/airflow/models/connection.py", line 519, in get_connection_from_secrets
    raise AirflowNotFoundException(f"The conn_id `{conn_id}` isn't defined")
airflow.exceptions.AirflowNotFoundException: The conn_id `google_cloud_default` isn't defined
[2024-05-18T19:32:26.531+0000] {taskinstance.py:1206} INFO - Marking task as UP_FOR_RETRY. dag_id=data_loader, task_id=upload_file, run_id=scheduled__2023-06-19T01:00:00+00:00, execution_date=20230619T010000, start_date=20240518T193226, end_date=20240518T193226
[2024-05-18T19:32:26.545+0000] {standard_task_runner.py:110} ERROR - Failed to execute job 329 for task upload_file (The conn_id `google_cloud_default` isn't defined; 1561)
[2024-05-18T19:32:26.574+0000] {local_task_job_runner.py:240} INFO - Task exited with return code 1
[2024-05-18T19:32:26.598+0000] {taskinstance.py:3498} INFO - 0 downstream tasks scheduled from follow-on schedule check
[2024-05-18T19:32:26.601+0000] {local_task_job_runner.py:222} INFO - ::endgroup::
