[2024-05-18T21:12:10.075+0000] {local_task_job_runner.py:120} INFO - ::group::Pre task execution logs
[2024-05-18T21:12:10.089+0000] {taskinstance.py:2076} INFO - Dependencies all met for dep_context=non-requeueable deps ti=<TaskInstance: data_loader.upload_file manual__2024-05-18T21:12:07.223712+00:00 [queued]>
[2024-05-18T21:12:10.096+0000] {taskinstance.py:2076} INFO - Dependencies all met for dep_context=requeueable deps ti=<TaskInstance: data_loader.upload_file manual__2024-05-18T21:12:07.223712+00:00 [queued]>
[2024-05-18T21:12:10.097+0000] {taskinstance.py:2306} INFO - Starting attempt 1 of 2
[2024-05-18T21:12:10.112+0000] {taskinstance.py:2330} INFO - Executing <Task(LocalFilesystemToGCSOperator): upload_file> on 2024-05-18 21:12:07.223712+00:00
[2024-05-18T21:12:10.121+0000] {warnings.py:110} WARNING - /home/***/.local/lib/python3.12/site-packages/***/task/task_runner/standard_task_runner.py:61: DeprecationWarning: This process (pid=179) is multi-threaded, use of fork() may lead to deadlocks in the child.
  pid = os.fork()

[2024-05-18T21:12:10.123+0000] {standard_task_runner.py:63} INFO - Started process 181 to run task
[2024-05-18T21:12:10.124+0000] {standard_task_runner.py:90} INFO - Running: ['***', 'tasks', 'run', 'data_loader', 'upload_file', 'manual__2024-05-18T21:12:07.223712+00:00', '--job-id', '376', '--raw', '--subdir', 'DAGS_FOLDER/data_loader.py', '--cfg-path', '/tmp/tmp3yk865qw']
[2024-05-18T21:12:10.127+0000] {standard_task_runner.py:91} INFO - Job 376: Subtask upload_file
[2024-05-18T21:12:10.172+0000] {task_command.py:426} INFO - Running <TaskInstance: data_loader.upload_file manual__2024-05-18T21:12:07.223712+00:00 [running]> on host a464b827924a
[2024-05-18T21:12:10.259+0000] {taskinstance.py:2648} INFO - Exporting env vars: AIRFLOW_CTX_DAG_OWNER='***' AIRFLOW_CTX_DAG_ID='data_loader' AIRFLOW_CTX_TASK_ID='upload_file' AIRFLOW_CTX_EXECUTION_DATE='2024-05-18T21:12:07.223712+00:00' AIRFLOW_CTX_TRY_NUMBER='1' AIRFLOW_CTX_DAG_RUN_ID='manual__2024-05-18T21:12:07.223712+00:00'
[2024-05-18T21:12:10.262+0000] {taskinstance.py:430} INFO - ::endgroup::
[2024-05-18T21:12:10.273+0000] {connection.py:274} WARNING - Connection schemes (type: google_cloud_platform) shall not contain '_' according to RFC3986.
[2024-05-18T21:12:10.275+0000] {base.py:84} INFO - Using connection ID 'googlecloud' for task execution.
[2024-05-18T21:12:10.322+0000] {taskinstance.py:441} INFO - ::group::Post task execution logs
[2024-05-18T21:12:10.323+0000] {taskinstance.py:2905} ERROR - Task failed with exception
Traceback (most recent call last):
  File "/home/airflow/.local/lib/python3.12/site-packages/airflow/models/taskinstance.py", line 465, in _execute_task
    result = _execute_callable(context=context, **execute_callable_kwargs)
             ^^^^^^^^^^^^^^^^^^^^^^^^^^^^^^^^^^^^^^^^^^^^^^^^^^^^^^^^^^^^^
  File "/home/airflow/.local/lib/python3.12/site-packages/airflow/models/taskinstance.py", line 432, in _execute_callable
    return execute_callable(context=context, **execute_callable_kwargs)
           ^^^^^^^^^^^^^^^^^^^^^^^^^^^^^^^^^^^^^^^^^^^^^^^^^^^^^^^^^^^^
  File "/home/airflow/.local/lib/python3.12/site-packages/airflow/models/baseoperator.py", line 400, in wrapper
    return func(self, *args, **kwargs)
           ^^^^^^^^^^^^^^^^^^^^^^^^^^^
  File "/home/airflow/.local/lib/python3.12/site-packages/airflow/providers/google/cloud/transfers/local_to_gcs.py", line 111, in execute
    hook.upload(
  File "/home/airflow/.local/lib/python3.12/site-packages/airflow/providers/google/cloud/hooks/gcs.py", line 550, in upload
    _call_with_retry(
  File "/home/airflow/.local/lib/python3.12/site-packages/airflow/providers/google/cloud/hooks/gcs.py", line 508, in _call_with_retry
    f()
  File "/home/airflow/.local/lib/python3.12/site-packages/google/cloud/storage/blob.py", line 2959, in upload_from_filename
    self._handle_filename_and_upload(
  File "/home/airflow/.local/lib/python3.12/site-packages/google/cloud/storage/blob.py", line 2827, in _handle_filename_and_upload
    with open(filename, "rb") as file_obj:
         ^^^^^^^^^^^^^^^^^^^^
IsADirectoryError: [Errno 21] Is a directory: '/opt/airflow/raw'
[2024-05-18T21:12:10.334+0000] {taskinstance.py:1206} INFO - Marking task as UP_FOR_RETRY. dag_id=data_loader, task_id=upload_file, run_id=manual__2024-05-18T21:12:07.223712+00:00, execution_date=20240518T211207, start_date=20240518T211210, end_date=20240518T211210
[2024-05-18T21:12:10.345+0000] {standard_task_runner.py:110} ERROR - Failed to execute job 376 for task upload_file ([Errno 21] Is a directory: '/opt/airflow/raw'; 181)
[2024-05-18T21:12:10.419+0000] {local_task_job_runner.py:240} INFO - Task exited with return code 1
[2024-05-18T21:12:10.447+0000] {taskinstance.py:3498} INFO - 0 downstream tasks scheduled from follow-on schedule check
[2024-05-18T21:12:10.451+0000] {local_task_job_runner.py:222} INFO - ::endgroup::
